Workbook

Sheet 入力シート
B2: ●アドバイザー 入力 担当 | E2: 平澤
D3: ※連名の場合は、連名者も記載
C4: 物件名 | D4: 伊藤友章 | E4: ﾌﾘｶﾞﾅ | F4: ｲﾄｳ ﾄﾓｱｷ
C5: 電話 | D5: ○○ ○○
C7: 現地(地番) | D7: 静岡県掛川市宮脇字五輪田1059番2,1059番9,1060番17
C9: 現住所 | D9: ▼▼▼▼▼▼▼▼▼▼▼▼
C11: 工務 | D11: 青島 | E11: =VLOOKUP($D11,入力シート!$E$43:$F$52,2,FALSE) -> aoshima.s@hakuto-k.jp
C13: IC | E13: =VLOOKUP($D13,入力シート!$G$43:$H$47,2,FALSE) -> #N/A
C15: LIXIL予約 | D15: モデルにつきSR見学なし
B20: ●設計 入力
C22: 基本設計 | D22: 倉田 | E22: =VLOOKUP($D22,入力シート!$C$43:$D$48,2,FALSE) -> kurata.tu@hakuto-k.jp | J22: PG有玉西モデル、想定ケジュール
C23: 詳細設計 | D23: 倉田 | E23: =VLOOKUP($D23,入力シート!$C$43:$D$48,2,FALSE) -> kurata.tu@hakuto-k.jp | J23: ■敷地調査6/28※確定予定
C24: 申請設計 | D24: 浜岡総合設計事務所 西原 | E24: =IF(D24=C55,D56,IF(D24=C58,D59)) -> k-nishi@proof.ocn.ne.jp | J24: ■敷地調査報告書7/6※確定予定
E25: =IF(D24=C55,D57,IF(D24=C58,D60)) -> 090-7034-9867 | J25: ■基本設計完了7/10
J26: ■平面詳細、基礎図完了7/20
C27: 上棟 | D27: 2025/1/14 | J27: ■プレカット図完了8/5
J28: ■都市計60条申請日8/5
C29: 確認申請 | D29: 2024/11/30 | J29: ■詳細設計＆構造計算完了8/15
J30: ■確認申請＆長期優良住宅申請完了8/25
C31: 長期申請 | D31: 2024/11/30 | J31: ■着工予定日9/3（最短）
J32: かつ土地決済の１０日後が着工目安
C33: 事前申請 | J33: 未確定↓↓↓
J34: ■土地決済日｜8月30日予定とすると9/10着工
C35: 着工予定 | D35: 2024/12/23
C37: 竣工予定 | D37: 2024/4
C42: ■基本設計担当 | E42: ■工務 | G42: ■IC
C43: 石澤 | D43: ishizawa.m@hakuto-k.jp | E43: 森下 | F43: morishita.s@hakuto-k.jp | G43: 水野 | H43: mizuno.m@hakuto-k.jp
C44: 有吉 | D44: ariyoshi.i@hakuto-k.jp | E44: 青島 | F44: aoshima.s@hakuto-k.jp | G44: 定村 | H44: sadamura.n@hakuto-k.jp
C45: 倉田 | D45: kurata.tu@hakuto-k.jp | E45: 品岡 | F45: shinaoka.m@hakuto-k.jp | G45: 有吉 | H45: ariyoshi.i@hakuto-k.jp
C46: ■詳細設計担当 | E46: 加藤 | F46: kato.h@hakuto-k.jp | G46: Kors 鈴木珠未さん | H46: tamami@l-kors.jp
C47: 石澤 | D47: ishizawa.m@hakuto-k.jp | E47: 藤原 | F47: fujiwara.r@hakuto-k.jp
C48: 有吉 | D48: ariyoshi.i@hakuto-k.jp | E48: 小池 | F48: koike.n@hakuto-k.jp
C49: 倉田 | D49: kurata.tu@hakuto-k.jp | E49: 岡田 | F49: okada.m@hakuto-k.jp
E50: 松下 | F50: matsushita.y@hakuto-k.jp
E51: 川原 | F51: kawahara.k@hakuto-k.jp
E52: 釜 | F52: kama.m@hakuto-k.jp
C54: ■申請設計事務所 | E54: ■アドバイザー
C55: 浜岡総合設計事務所 西原 | E55: 白都 | F55: hakuto.t@hakuto-k.jp
D56: k-nishi@proof.ocn.ne.jp | E56: 鵜飼 | F56: ukai.r@hakuto-k.jp
D57: 090-7034-9867
...

Sheet 給排水図
A3: 給排水経路 確認依頼
B6: 依頼先 | N6: 依頼者
B7: 愛管株式会社 御中 | N7: 株式会社LIFEFUND ARRCH
B8: 長谷 | D8: 様 | F8: i-kan.hakuto@i-kan.co.jp | N8: 基本設計 | Q8: =入力シート!D22 -> 倉田 | S8: =入力シート!E22 -> kurata.tu@hakuto-k.jp
N9: 詳細設計 | Q9: =入力シート!D23 -> 倉田 | S9: =入力シート!E23 -> kurata.tu@hakuto-k.jp
B10: 〒438-0002 | N10: 〒432-8023
B11: 静岡県磐田市大久保475番地7 | N11: 静岡県浜松市中央区鴨江3丁目70番23号
B12: Tel：0538-31-7700 | G12: Fax：0538-31-7701 | N12: Tel：053-488-8910 | S12: Fax：053-488-8911
B13: 携帯：080-6974-8911
B18: 物件名
C19: =入力シート!D4 -> 伊藤友章
N20: 依頼日 | T20: 期限日
N21: 2024/8/1 | T21: 2024/9/1
X22: ※基本 1週間
B23: 建設地
C24: =入力シート!D7 -> 静岡県掛川市宮脇字五輪田1059番2,1059番9,1060番17
B27: 現場担当 | G27: =入力シート!D11 -> 青島 | J27: =入力シート!E11 -> aoshima.s@hakuto-k.jp
B29: 備考

Sheet プレカット_ハイビック
A3: プレカット図面 作成依頼
B6: 依頼先 | N6: 依頼者
B7: ハイビック株式会社 御中 | N7: 株式会社LIFEFUND
C8: 大久保 | E8: 様 | G8: a.okubo@hivic.co.jp | N8: 基本設計 | Q8: =入力シート!D22 -> 倉田 | S8: =入力シート!E22 -> kurata.tu@hakuto-k.jp
N9: 詳細設計 | Q9: =入力シート!D23 -> 倉田 | S9: =入力シート!E23 -> kurata.tu@hakuto-k.jp
C10: 〒434-0004 | N10: 〒432-8023
C11: 静岡県浜松市浜北区宮口2461 | N11: 静岡県浜松市中央区鴨江3丁目70番23号
C12: Tel：053-580-1185 | H12: Fax：053-582-3719 | N12: Tel：053-488-8910 | S12: Fax：053-488-8911
C13: 携帯：070-1295-6433
B17: 物件名
C18: =入力シート!D4 -> 伊藤友章
S19: 依頼日
S20: 2024/10/22
B22: 現地
C23: =入力シート!D7 -> 静岡県掛川市宮脇字五輪田1059番2,1059番9,1060番17
B26: 現場担当 | G26: =入力シート!D11 -> 青島 | J26: =入力シート!E11 -> aoshima.s@hakuto-k.jp
B28: 確認申請予定 | G28: =入力シート!D29 -> 2024/11/30
B30: 上棟予定 | G30: =入力シート!D27 -> 2025/1/14
B32: 申請設計事務所 | G32: =入力シート!D24 -> 浜岡総合設計事務所 西原 | N32: さん | P32: =入力シート!E24 -> k-nishi@proof.ocn.ne.jp
B34: 構造計算 | G34: =入力シート!C55 -> 浜岡総合設計事務所 西原 | N34: さん | P34: =入力シート!D56 -> k-nishi@proof.ocn.ne.jp
B36: 屋根葺材 | G36: ガルバニウム鋼板
B38: 屋根勾配 | G38: 0.5寸
B40: 天井高 | G40: 2400
C48: プレカット図納期期限 10/31
C50: プレカット図面については、
E52: 上記 設計、現場担当、申請担当、構造担当 まで メールお願い致します。

Sheet プレカット_SKY
A3: プレカット図面 作成依頼
A6: 依頼先 | I6: 依頼先 | Q6: 依頼者
A7: 株式会社 丸八 御中 | I7: 株式会社 スカイ 御中 | Q7: 株式会社LIFEFUND
B8: 鈴木 様 | J8: 岡村 様 | Q8: 基本設計 | S8: =入力シート!D22 -> 倉田 | U8: =入力シート!E22 -> kurata.tu@hakuto-k.jp
B9: yuya-suzuki@maruhachi.info | J9: okamura.yuuta@sky-jp.com | Q9: 詳細設計 | S9: =入力シート!D23 -> 倉田 | U9: =入力シート!E23 -> kurata.tu@hakuto-k.jp
B10: 〒436-0038 | J10: 〒438-0111 | Q10: 〒432-8023
B11: 静岡県掛川市領家1583-1 | J11: 静岡県磐田市上野部505-15 | Q11: 静岡県浜松市中央区鴨江3丁目70番23号
B12: Tel：0537-22-1919 | J12: Tel：0539-62-1077 | Q12: Tel：053-488-8910、Fax：053-488-8911
B13: Fax：0537-22-1978 | J13: Fax：053962-1078
B14: 携帯：080-8260-4690 | J14: 携帯：070-2248-8081
B18: 物件名
C19: =入力シート!D4 -> 伊藤友章
S20: 依頼日
S21: 2021/4/12
B22: 現地
C23: =入力シート!D7 -> 静岡県掛川市宮脇字五輪田1059番2,1059番9,1060番17
B26: 現場担当 | G26: =入力シート!D11 -> 青島 | J26: =入力シート!E11 -> aoshima.s@hakuto-k.jp
B28: 確認申請予定 | G28: =入力シート!D29 -> 2024/11/30
B30: 上棟予定 | G30: =入力シート!D27 -> 2025/1/14
B32: 申請設計事務所 | G32: =入力シート!D24 -> 浜岡総合設計事務所 西原 | N32: さん | P32: =入力シート!E24 -> k-nishi@proof.ocn.ne.jp
P33: =入力シート!E25 -> 090-7034-9867
B35: 構造計算 | G35: =入力シート!C55 -> 浜岡総合設計事務所 西原 | N35: さん | P35: =入力シート!D56 -> k-nishi@proof.ocn.ne.jp
B37: 屋根葺材 | G37: ガルバニウム鋼板
B39: 屋根勾配 | G39: 2.0寸
B41: 天井高 | G41: 2400
C45: プレカット図面の納品日については、最短で来そうな日程分かりましたら
C47: 教えていただきたいです。 (メールで大丈夫です。)
C51: プレカット図面については、
E53: 上記 設計、現場担当、申請担当、構造担当 まで メールお願い致します。

Sheet 太陽光
A2: 【太陽光発電システム見積依頼書】
B4: 株式会社LIFEFUND ARRCH 担当者 | P4: =入力シート!D22 -> 倉田 | Y4: 記入日 | AD4: / /
B5: 建築予定住所 | F5: =入力シート!D7 -> 静岡県掛川市宮脇字五輪田1059番2,1059番9,1060番17 | U5: お客様名 | Y5: =入力シート!D4 -> 伊藤友章
B6: ご家族構成 | F6: 大人 | H6: 2 | J6: 名 | L6: 子供 | N6: ? | P6: 名（わかる範囲で構いません。）
B7: 備考 | F7: 現在子供はいない 将来２人予定
B9: １ 基本確認事項 | P9: ※□の中にレ点をご記入ください。
B11: 1．屋根に影ができる障害物がない。 | R11: はい | V11: いいえ | Y11: （※隣接する建物（家屋・電柱・樹木）がお宅の屋根高以上ある場合）
B12: 2．海岸から直線距離で1km以上離れている。 | R12: はい | V12: いいえ
B14: ※上記にて「いいえ」がある場合
B15: 1．影がある場合： 障害物の種類( | S15: ) | T15: 障害物の高さ (屋根高よりも約 | AD15: M高い位置) | AI15: 方角( | AL15: )
B16: 2．海岸から1km以内の立地の場合： 海岸からの直線距離(約 | U16: km)
B19: ２ 添付図面 | P19: ※□の中にレ点をご記入ください。
B21: 立面図 平面図 （ 断面（矩計）図 屋根伏せ図） 無し
B24: 3 屋根について | M24: ※図面に記載されている場合は□の中にレ点を、記載されていなければ（ ）にご記入ください。
B26: 屋根材 金属縦葺き 金属横葺き その他（ ）
B28: 勾配 （ 寸） | O28: □野地板（厚さ・種類）（ ） □軒・けらば寸法（ mm）
B32: 4 見積希望プラン | U32: ※□の中にレ点をご記入ください。
B34: メーカー | E34: Qセルズ その他（ ） | Q34: モジュール型番 | X34: ARRCH様標準 それ以外
B36: 見積システム容量 | L36: 最大システム | S36: 希望容量 | X36: 6 | AB36: ｋｗ
B37: パワコン台数指定 | J37: 1 | P37: 台 | R37: パワコン設置場所指定 | Z37: 屋内設置 屋外設置
B39: 蓄電池 | J39: 希望する 希望しない
B42: ※上記にて「希望する」場合
B43: 特定負荷型 全負荷型
A45: 電器堂使用欄
B46: 見積り用提出書類確認
B47: □本シート □立面図 □平面図 （□断面（矩計）図 □屋根伏せ図 □配置図）
B49: 部署 | M49: 担当者 | X49: 日付 | AB49: 年 月 日

Sheet 地盤調査
A3: 地盤調査依頼
B6: 依頼先 | N6: 依頼者
B7: 報国エンジニアリング株式会社 御中 | N7: 株式会社LIFEFUND ARRCH
B8: 上田 | D8: 様 | F8: ueda@hokoku-eng.com | N8: 基本設計 | Q8: =入力シート!D22 -> 倉田 | S8: =入力シート!E22 -> kurata.tu@hakuto-k.jp
N9: 詳細設計 | Q9: =入力シート!D23 -> 倉田 | S9: =入力シート!E23 -> kurata.tu@hakuto-k.jp
B10: 〒422-8057 | N10: 〒432-8023
B11: 静岡県静岡市駿河区見瀬239-1 | N11: 静岡県浜松市中央区鴨江3丁目70番23号
B12: Tel：054-292-5488 | G12: Fax：054-292-5490 | N12: Tel：053-488-8910 | S12: Fax：053-488-8911
B13: 携帯：080-5705-1616
B18: 物件名
C19: =入力シート!D4 -> 伊藤友章
T20: 依頼日
T21: 2024/8/1
B23: 建設地
C24: =入力シート!D7 -> 静岡県掛川市宮脇字五輪田1059番2,1059番9,1060番17
B27: 現場担当 | G27: =入力シート!D11 -> 青島 | J27: =入力シート!E11 -> aoshima.s@hakuto-k.jp
B29: 営業担当 | G29: =入力シート!E2 -> 平澤 | J29: =入力シート!F2 -> 0
C33: 調査結果については、上記 設計、現場、営業担当 まで メールお願い致します。
B37: 備考 | G37: 解体工事が8/29までかかるため
G39: 地盤調査日は8/30（金）でお願いします。
G41: 即着工したいため、速報すぐ欲しいです

Sheet LIXIL
A3: LIXILショールーム 予約確認
B6: 依頼先 | N6: 依頼者
B7: ㈱LIXIL 御中 | N7: 株式会社LIFEFUND ARRCH
B8: 粟野 | D8: 様 | F8: tomohito.awano@lixil.com | N8: 基本設計 | Q8: =入力シート!D22 -> 倉田 | S8: =入力シート!E22 -> kurata.tu@hakuto-k.jp
N9: 詳細設計 | Q9: =入力シート!D23 -> 倉田 | S9: =入力シート!E23 -> kurata.tu@hakuto-k.jp
B10: 〒435-0016 | N10: 〒432-8023
B11: 静岡県浜松市東区和田町660-6 | N11: 静岡県浜松市中央区鴨江3丁目70番23号
B12: Tel：053-411-1666 | G12: Fax：053-411-1667 | N12: Tel：053-488-8910 | S12: Fax：053-488-8911
B18: 物件名
C19: =入力シート!D4 -> 伊藤友章
N20: 依頼日 | T20: 予約日時
N21: 2023/4/27 | T21: =入力シート!D15 -> モデルにつきSR見学なし
B23: 建設地
C24: =入力シート!D7 -> 静岡県掛川市宮脇字五輪田1059番2,1059番9,1060番17
B26: 営業担当 | G26: =入力シート!E2 -> 平澤 | N26: =入力シート!F2 -> 0
B28: 現場担当 | G28: =入力シート!D11 -> 青島 | N28: =入力シート!E11 -> aoshima.s@hakuto-k.jp
B30: IC担当 | G30: =入力シート!D13 -> 0 | N30: =入力シート!E13 -> #N/A
B32: 上棟予定 | G32: =入力シート!D27 -> 2025/1/14
B34: キッチン | H34: ES | L34: ペニンシュラ | Q34: その他 （ | X34: ）
B36: カップボード | H36: LIXIL | L36: 持ち込み | Q36: その他 （ | T36: 未定 | X36: ）
B38: ユニットバス | H38: LIXIL | Q38: その他 （ | X38: ）
B40: トイレ① | H40: LIXIL | Q40: その他 （ | T40: ハーモJ | X40: ）
B42: トイレ② | H42: 無し | L42: LIXIL | Q42: その他 （ | T42: ベーシア手洗ﾀﾝｸ | X42: ）
B44: スロップシンク | H44: 無し | L44: TOTO
B46: 備考

Sheet ルフロ図依頼
A3: 換気計算・ルフロ図 作成依頼
B6: 依頼先 | N6: 依頼者
B7: (株)電器堂 パートナー開発 御中 | N7: 株式会社LIFEFUND ARRCH
B8: 大塚 | D8: 様 | F8: otsukan@denkido.jp | N8: 基本設計 | Q8: =入力シート!D22 -> 倉田 | S8: =入力シート!E22 -> kurata.tu@hakuto-k.jp
N9: 詳細設計 | Q9: =入力シート!D23 -> 倉田 | S9: =入力シート!E23 -> kurata.tu@hakuto-k.jp
C10: 〒432-8055
C11: 静岡県浜松市南区卸本町2000-15 | N11: 〒432-8023
C12: Tel：053-441-3130 | H12: Fax：053-441-6508 | N12: 静岡県浜松市中央区鴨江3丁目70番23号
C13: 携帯：080-4535-4226 | N13: Tel：053-488-8910 | S13: Fax：053-488-8911
B15: 日本住環境(株) 御中
B16: 安藤 | D16: 様 | F16: ando-m@njkk.co.jp
B21: 物件名
C22: =入力シート!D4 -> 伊藤友章
N23: 依頼日 | T23: 期限日
N24: 2024/3/9 | T24: 2024/3/18
X25: ※基本 1週間
B26: 建設地
C27: =入力シート!D7 -> 静岡県掛川市宮脇字五輪田1059番2,1059番9,1060番17
B30: 現場担当 | G30: =入力シート!D11 -> 青島 | J30: =入力シート!E11 -> aoshima.s@hakuto-k.jp
B32: 階高 | H32: 2階建て | M32: 平屋
V33: 防火指定あり
B34: 換気フード色 | H34: シルバー | M34: ブラック | R34: ホワイト | V34: 防火指定無し
B36: 添付図面(JW) | H36: 平面 | K36: 立面 | N36: プレカット図(配管ルート記載)
B38: 確認申請予定 | G38: =入力シート!D29 -> 2024/11/30 | K38: ※申請に必要
B40: 着工予定 | G40: =入力シート!D35 -> 2024/12/23
B42: 竣工予定 | G42: =入力シート!D37 -> 2024/4
B44: 備考

Sheet 事前依頼
A3: 申請依頼
B6: 依頼先 | N6: 依頼者
C7: =入力シート!C55 -> 浜岡総合設計事務所 西原 | K7: 様 | N7: 株式会社LIFEFUND ARRCH
F8: =入力シート!D56 -> k-nishi@proof.ocn.ne.jp | N8: 基本設計 | Q8: =入力シート!D22 -> 倉田 | S8: =入力シート!E22 -> kurata.tu@hakuto-k.jp
N9: 詳細設計 | Q9: =入力シート!D23 -> 倉田 | S9: =入力シート!E23 -> kurata.tu@hakuto-k.jp
C10: =入力シート!C58 -> カーザ建築設計室 橋本 | K10: 様 | N10: 〒432-8023
F11: =入力シート!D59 -> nobu.net.com@cy.tnc.ne.jp | N11: 静岡県浜松市中央区鴨江3丁目70番23号
N12: Tel：053-488-8910 | S12: Fax：053-488-8911
B17: 物件名 | D17: =入力シート!F4 -> ｲﾄｳ ﾄﾓｱｷ
D18: =入力シート!D4 -> 伊藤友章
T19: 依頼日
T20: 2023/4/27
B22: 建設地
C23: =入力シート!D7 -> 静岡県掛川市宮脇字五輪田1059番2,1059番9,1060番17
B26: 現場担当 | G26: =入力シート!D11 -> 青島 | J26: =入力シート!E11 -> aoshima.s@hakuto-k.jp
B28: 4者打合せ日 | G28: =入力シート!D33 -> 0 | K28: ※3日前までに、法規・構造・外皮 チェックバック
B30: 確認申請予定 | G30: =入力シート!D29 -> 2024/11/30
B32: 長期優良申請予定 | G32: =入力シート!D31 -> 2024/11/30
B34: ルフロ図予定 | G34: =ルフロ図依頼!T24 -> 2024/3/18
B36: 申請図面 日付 | G36: ※4者打合せ後 図面送る際に指定させていただきます。
B38: 現住所 | G38: =入力シート!D9 -> ▼▼▼▼▼▼▼▼▼▼▼▼
B40: 電話番号 | G40: =入力シート!D5 -> ○○ ○○

Sheet 申請 依頼
A3: 申請依頼
B6: 依頼先 | N6: 依頼者
C7: =入力シート!C55 -> 浜岡総合設計事務所 西原 | K7: 様 | N7: 株式会社LIFEFUND ARRCH
F8: =入力シート!D56 -> k-nishi@proof.ocn.ne.jp | N8: 基本設計 | Q8: =入力シート!D22 -> 倉田 | S8: =入力シート!E22 -> kurata.tu@hakuto-k.jp
N9: 詳細設計 | Q9: =入力シート!D23 -> 倉田 | S9: =入力シート!E23 -> kurata.tu@hakuto-k.jp
C10: =入力シート!C58 -> カーザ建築設計室 橋本 | K10: 様 | N10: 〒432-8023
F11: =入力シート!D59 -> nobu.net.com@cy.tnc.ne.jp | N11: 静岡県浜松市中央区鴨江3丁目70番23号
N12: Tel：053-488-8910 | S12: Fax：053-488-8911
B17: 物件名 | D17: =入力シート!F4 -> ｲﾄｳ ﾄﾓｱｷ
D18: =入力シート!D4 -> 伊藤友章
T19: 依頼日
T20: 2023/4/27
B22: 建設地
C23: =入力シート!D7 -> 静岡県掛川市宮脇字五輪田1059番2,1059番9,1060番17
B26: 現場担当 | G26: =入力シート!D11 -> 青島 | J26: =入力シート!E11 -> aoshima.s@hakuto-k.jp
B28: 打合せ | G28: 終了済み
B30: 確認申請予定 | G30: =入力シート!D29 -> 2024/11/30
B32: 長期優良申請予定 | G32: =入力シート!D31 -> 2024/11/30
B34: ルフロ図予定 | G34: =ルフロ図依頼!T24 -> 2024/3/18
B36: 申請図面 日付 | G36: ●/×
B38: 現住所 | G38: =入力シート!D9 -> ▼▼▼▼▼▼▼▼▼▼▼▼
B40: 電話番号 | G40: =入力シート!D5 -> ○○ ○○

Sheet FAX
A3: FAX 送信紙
B6: 依頼先 | N6: 依頼者
B7: 南海プライウッド | H7: 御中 | N7: 株式会社LIFEFUND ARRCH
O8: 設計担当
F9: ご担当者 | J9: 様 | O9: =入力シート!D22 -> 倉田 | Q9: =入力シート!E22 -> kurata.tu@hakuto-k.jp
N10: 〒432-8023
N11: 静岡県浜松市中央区鴨江3丁目70番23号
N12: Tel：053-488-8910 | S12: Fax：053-488-8911
B18: 物件名
C19: =入力シート!D4 -> 伊藤友章
N20: 依頼日 | T20: 期限日
N21: 2023/4/27 | T21: 2023/4/27
B23: 建設地
C24: =入力シート!D7 -> 静岡県掛川市宮脇字五輪田1059番2,1059番9,1060番17
B27: 現場担当 | G27: =入力シート!D11 -> 青島 | J27: =入力シート!E11 -> aoshima.s@hakuto-k.jp
B29: 備考

Sheet FAX (カタログ依頼)
A3: FAX 送信紙
B6: 依頼先 | N6: 依頼者
B7: 〇〇〇〇〇〇〇〇 | H7: 御中 | N7: 株式会社LIFEFUND ARRCH
O8: 設計担当
F9: ご担当者 | J9: 様 | O9: =入力シート!D22 -> 倉田 | Q9: =入力シート!E22 -> kurata.tu@hakuto-k.jp
N10: 〒432-8023
G11: 052-218-3187 | H11: (052)504-1550 | N11: 静岡県浜松市中央区鴨江3丁目70番23号
N12: Tel：053-488-8910 | S12: Fax：053-488-8911
G13: 44419
B18: いつもお世話になっております。
B22: カタログ依頼をさせていただきます。
C26: 総合カタログ | N26: ○ | O26: 部
C32: よろしくお願いいたします。
F35: 432-8023
D36: 送付先：静岡県浜松市中区鴨江3丁目70番23号
N38: 株式会社LIFEFUND ARRCH 石澤 宛
D40: Tel：053-488-8910
Q44: よろしくお願いします。

Sheet クリナップ
A3: クリナップショールーム 予約確認
B6: 依頼先 | N6: 依頼者
C7: クリナップ | N7: 株式会社LIFEFUND ARRCH
B8: 安井 | D8: 様 | F8: y.yasui@cleanup.jp | O8: 設計担当
O9: =入力シート!D22 -> 倉田 | Q9: =入力シート!E22 -> kurata.tu@hakuto-k.jp
B10: 〒435-0017 | N10: 〒432-8023
B11: 静岡県浜松市東区薬師町79-2 | N11: 静岡県浜松市中央区鴨江3丁目70番23号
B12: Tel：053-423-0180 | G12: Fax：053-423-0181 | N12: Tel：053-488-8910 | S12: Fax：053-488-8911
B13: 携帯：090-3516-9504
B18: 物件名
C19: =LIXIL!$C$19 -> 伊藤友章
N20: 依頼日 | T20: 予約日時
N21: 2023/4/27 | AB21: クリナップ
T22: 予約番号
B23: 建設地 | AB23: ito.n@hakuto-k.jp | AD23: ＩＤ
C24: =入力シート!D7 -> 静岡県掛川市宮脇字五輪田1059番2,1059番9,1060番17 | AB24: hakuto8910 | AD24: パス
AB26: ※予約はネットにて予約する
B27: 現場担当 | G27: =LIXIL!G28 -> 青島 | N27: =LIXIL!N28 -> aoshima.s@hakuto-k.jp
B29: IC担当 | G29: =LIXIL!G30 -> 0 | N29: =LIXIL!N30 -> #N/A
B31: 上棟予定 | G31: =LIXIL!G32 -> 2025/1/14
B33: キッチン | H33: ステディア | Q33: その他 （ | T33: TOTOも検討 | X33: ）
B35: カップボード | H35: ステディア | Q35: その他 （ | T35: TOTOも検討 | X35: ）
B37: ユニットバス | Q37: その他 （ | T37: ＴＯＴＯ | X37: ）
B39: 洗面① | H39: 造作
B41: 洗面② | H41: 無し | L41: 造作
B43: 備考 | G43: 見積り、プランについては、 | N43: =O9 -> 倉田 | P43: =G27 -> 青島 | R43: =G29 -> 0
S45: 宛にお願い致します。

Sheet プレカット_天竜プレカット
A3: プレカット図面 作成依頼
B6: 依頼先 | N6: 依頼者
B7: 天竜プレカット事業協同組合 御中 | N7: 株式会社LIFEFUND ARRCH
B8: 川瀬 | D8: 様 | F8: y.kawase@tenryuprecut.jp | O8: 設計担当
B9: 廣瀬 | D9: 様 | F9: s.hirose@tenryuprecut.jp | O9: =入力シート!D22 -> 倉田 | Q9: =入力シート!E22 -> kurata.tu@hakuto-k.jp
B10: 〒431-3306 | N10: 〒432-8023
B11: 静岡県浜松市天竜区船明2661番地 | N11: 静岡県浜松市中央区鴨江3丁目70番23号
B12: Tel：053-925-6311 | G12: Fax：053-925-6371 | N12: Tel：053-488-8910 | S12: Fax：053-488-8911
B17: 物件名
C18: =入力シート!D4 -> 伊藤友章
N19: 依頼日 | T19: 期限日
X21: ※基本 1週間
B22: 建設地
C23: =入力シート!D7 -> 静岡県掛川市宮脇字五輪田1059番2,1059番9,1060番17
B26: 現場担当 | G26: =入力シート!D11 -> 青島 | I26: =入力シート!E11 -> aoshima.s@hakuto-k.jp
B28: 確認申請予定 | G28: =入力シート!D29 -> 2024/11/30
B30: 上棟予定 | G30: =入力シート!D27 -> 2025/1/14
B32: 申請設計事務所 | G32: =入力シート!D24 -> 浜岡総合設計事務所 西原 | N32: さん | P32: =入力シート!E24 -> k-nishi@proof.ocn.ne.jp
B34: 構造計算 | G34: =入力シート!C55 -> 浜岡総合設計事務所 西原 | N34: さん | P34: =入力シート!D56 -> k-nishi@proof.ocn.ne.jp
B36: 屋根葺材 | G36: ガルバニウム鋼板
B38: 屋根勾配 | G38: 2.0寸
B40: 天井高 | G40: 2400
C50: プレカット図面については、
E52: 上記 設計、現場担当、申請担当、構造担当 まで メールお願い致します。
