Workbook

Sheet 見積表 (平屋用) 
B2: 建築本体価格 見積書
I3: PJ-Ver1.00
E4: 邸新築工事 | H4: 2024.8.24
I5: 見積No.001
C7: １階施工床面積 | E7: =ROUNDDOWN(H8*0.3025,1) -> 0
B8: 平 屋 | J8: ㎡
F9: 坪 | H9: 小数点第3位切り捨て
C10: 小数点第2位切り捨て
A12: ① | B12: 基準価格 | C12: 25 | F12: ＝ | H12: 15400000
C13: （坪） | H13: ＋
A14: ② | B14: 面積増減 | C14: =E7-C12 -> -25 | D14: × | E14: 380000 | F14: ＝ | H14: =C14*E14 -> -9500000
B15: （基準坪数からの増減） | C15: （坪） | E15: 建築面積（坪）
H16: ⇓
A18: 標準工事の合計 （ ① ② の 合 計 ） | F18: ＝ | H18: =H12+H14 -> 5900000
A20: ③ | B20: オプション工事 | C20: （標準工事に含まれない項目＝オプション）
B21: 項目 | E21: 単価 | F21: 単位 | G21: 数量 | H21: 金額
B22: =抽出オプション!A3 -> 建具追加（3尺巾） | E22: =抽出オプション!B3 -> 30000 | F22: =抽出オプション!C3 -> 円 | G22: =抽出オプション!D3 -> 2 | H22: =抽出オプション!E3 -> 60000
B23: =抽出オプション!A4 -> 3尺可動棚追加 | E23: =抽出オプション!B4 -> 26000 | F23: =抽出オプション!C4 -> ヵ所 | G23: =抽出オプション!D4 -> 1 | H23: =抽出オプション!E4 -> 26000
B24: =抽出オプション!A5 -> 6尺可動棚追加 | E24: =抽出オプション!B5 -> 39000 | F24: =抽出オプション!C5 -> ヵ所 | G24: =抽出オプション!D5 -> 1 | H24: =抽出オプション!E5 -> 39000
B25: =抽出オプション!A6 -> 6尺枕棚＋ハンガーパイプ | E25: =抽出オプション!B6 -> 14800 | F25: =抽出オプション!C6 -> 式 | G25: =抽出オプション!D6 -> 1 | H25: =抽出オプション!E6 -> 14800
B26: =抽出オプション!A7 -> オプション工事予算 | E26: =抽出オプション!B7 -> 1640000 | F26: =抽出オプション!C7 -> 式 | G26: =抽出オプション!D7 -> 1 | H26: =抽出オプション!E7 -> 1640000
B27: =抽出オプション!A8 | E27: =抽出オプション!B8 | F27: =抽出オプション!C8 | G27: =抽出オプション!D8 | H27: =抽出オプション!E8
B28: =抽出オプション!A9 | E28: =抽出オプション!B9 | F28: =抽出オプション!C9 | G28: =抽出オプション!D9 | H28: =抽出オプション!E9
B29: =抽出オプション!A10 | E29: =抽出オプション!B10 | F29: =抽出オプション!C10 | G29: =抽出オプション!D10 | H29: =抽出オプション!E10
B30: =抽出オプション!A11 | E30: =抽出オプション!B11 | F30: =抽出オプション!C11 | G30: =抽出オプション!D11 | H30: =抽出オプション!E11
B31: =抽出オプション!A12 | E31: =抽出オプション!B12 | F31: =抽出オプション!C12 | G31: =抽出オプション!D12 | H31: =抽出オプション!E12
B32: =抽出オプション!A13 | E32: =抽出オプション!B13 | F32: =抽出オプション!C13 | G32: =抽出オプション!D13 | H32: =抽出オプション!E13
B33: =抽出オプション!A14 | E33: =抽出オプション!B14 | F33: =抽出オプション!C14 | G33: =抽出オプション!D14 | H33: =抽出オプション!E14
... B39: =抽出オプション!A20 | E39: =抽出オプション!B20 | F39: =抽出オプション!C20 | G39: =抽出オプション!D20 | H39: =抽出オプション!E20
B40: 標準外の工事 | F40: ＝ | H40: =全オプション!E1 -> 1779800 | K40: =SUM(H21:I39) -> 1779800
B42: 建築本体工事費用 | C42: （税抜き） | D42: （① ② ③ の 合 計） | F42: ＝ | H42: =ROUNDDOWN(H18+H40,-4) -> 7670000
H43: 千円以下切り捨て
B44: 建物消費税 | C44: (10%) | F44: ＝ | H44: =ROUNDDOWN(H42*0.1,0) -> 767000
B46: 建築本体工事費用 | C46: （税込み） | F46: ＝ | H46: =H42+H44 -> 8437000

Sheet 見積表 (2F用)
B2: 建築本体価格 見積書
I3: PJ-Ver1.00
B4: 伊藤 友章 | E4: 邸新築工事 | H4: 45548
B5: 静岡県掛川市宮脇字五輪田1059番2、9／1060番17 | I5: 見積No.001
C7: １階施工床面積 | E7: =ROUNDDOWN(H7*0.3025,1) -> 19 | F7: 坪 | H7: 62.93 | J7: ㎡
B8: ２階建て | C8: ２階施工床面積 | E8: =ROUNDDOWN(H8*0.3025,1) -> 15 | F8: 坪 | H8: 49.69 | J8: ㎡
C9: 延べ施工床面積 | E9: =E7+E8 -> 34 | F9: 坪 | H9: 小数点第3位切り捨て
C10: 小数点第2位切り捨て
A12: ① | B12: 基準価格 | C12: 30 | F12: ＝ | H12: 15600000
C13: （坪） | H13: ＋
A14: ② | B14: 面積増減 | C14: =E9-C12 -> 4 | D14: × | E14: 313000 | F14: ＝ | H14: =C14*E14 -> 1252000
B15: （基準坪数からの増減） | C15: （坪） | E15: 建築面積（坪） | H15: ＋
A16: ③ | B16: 下屋面積 | C16: =IF(E7-E8<0,0,E7-E8) -> 4 | D16: × | E16: 134000 | F16: ＝ | H16: =C16*E16 -> 536000
B17: （１階床面積 - ２階床面積） | C17: （坪） | E17: 建築面積（坪） | H17: ⇓
A18: 標準工事の合計 （ ① ② ③ の 合 計 ） | F18: ＝ | H18: =H12+H14+H16 -> 17388000
A20: ④ | B20: オプション工事 | C20: （標準工事に含まれない項目＝オプション）
B21: 項目 | E21: 単価 | F21: 単位 | G21: 数量 | H21: 金額
B22: =抽出オプション!A3 -> 建具追加（3尺巾） | E22: =抽出オプション!B3 -> 30000 | F22: =抽出オプション!C3 -> 円 | G22: =抽出オプション!D3 -> 2 | H22: =抽出オプション!E3 -> 60000
B23: =抽出オプション!A4 -> 3尺可動棚追加 | E23: =抽出オプション!B4 -> 26000 | F23: =抽出オプション!C4 -> ヵ所 | G23: =抽出オプション!D4 -> 1 | H23: =抽出オプション!E4 -> 26000
B24: =抽出オプション!A5 -> 6尺可動棚追加 | E24: =抽出オプション!B5 -> 39000 | F24: =抽出オプション!C5 -> ヵ所 | G24: =抽出オプション!D5 -> 1 | H24: =抽出オプション!E5 -> 39000
B25: =抽出オプション!A6 -> 6尺枕棚＋ハンガーパイプ | E25: =抽出オプション!B6 -> 14800 | F25: =抽出オプション!C6 -> 式 | G25: =抽出オプション!D6 -> 1 | H25: =抽出オプション!E6 -> 14800
B26: =抽出オプション!A7 -> オプション工事予算 | E26: =抽出オプション!B7 -> 1640000 | F26: =抽出オプション!C7 -> 式 | G26: =抽出オプション!D7 -> 1 | H26: =抽出オプション!E7 -> 1640000
B27: =抽出オプション!A8 | E27: =抽出オプション!B8 | F27: =抽出オプション!C8 | G27: =抽出オプション!D8 | H27: =抽出オプション!E8
B28: =抽出オプション!A9 | E28: =抽出オプション!B9 | F28: =抽出オプション!C9 | G28: =抽出オプション!D9 | H28: =抽出オプション!E9
B29: =抽出オプション!A10 | E29: =抽出オプション!B10 | F29: =抽出オプション!C10 | G29: =抽出オプション!D10 | H29: =抽出オプション!E10
B30: =抽出オプション!A11 | E30: =抽出オプション!B11 | F30: =抽出オプション!C11 | G30: =抽出オプション!D11 | H30: =抽出オプション!E11
B31: =抽出オプション!A12 | E31: =抽出オプション!B12 | F31: =抽出オプション!C12 | G31: =抽出オプション!D12 | H31: =抽出オプション!E12
B32: =抽出オプション!A13 | E32: =抽出オプション!B13 | F32: =抽出オプション!C13 | G32: =抽出オプション!D13 | H32: =抽出オプション!E13
B33: =抽出オプション!A14 | E33: =抽出オプション!B14 | F33: =抽出オプション!C14 | G33: =抽出オプション!D14 | H33: =抽出オプション!E14
... B39: =抽出オプション!A20 | E39: =抽出オプション!B20 | F39: =抽出オプション!C20 | G39: =抽出オプション!D20 | H39: =抽出オプション!E20
B40: 標準外の工事 | F40: ＝ | H40: =全オプション!E1 -> 1779800 | K40: =SUM(H21:I39) -> 1779800
B42: 建築本体工事費用 | C42: （税抜き） | D42: （① ② ③ ④ の 合 計） | F42: ＝ | H42: =ROUNDDOWN(H18+H40,-4) -> 19160000
H43: 千円以下切り捨て
B44: 建物消費税 | C44: (10%) | F44: ＝ | H44: =ROUNDDOWN(H42*0.1,0) -> 1916000
B46: 建築本体工事費用 | C46: （税込み） | F46: ＝ | H46: =H42+H44 -> 21076000

Sheet 全オプション
A1: ■ ITEM OPTION | E1: =抽出オプション!E1 -> 1779800
A2: 項 目 | B2: 単価 | C2: 単位 | D2: 数量 | E2: 税抜金額 | H2: 原価単価 | I2: 原価合計 | J2: 利益率 | K2: 実物件名
A3: 外部袖壁（M:ﾓｼﾞｭｰﾙ長さ） | B3: =ROUNDUP(H3/0.7,-1) -> 75000 | C3: M | D3: 0 | E3: =B3*D3 -> 0 | F3: =IF(D3>0,ROW(),"") | H3: =(2000*2)+(5500*5)+(5000)+10000+6000 -> 52500 | I3: =H3*D3 -> 0 | J3: =1-I3/E3 -> #DIV/0! | K3: （EXﾊｲﾊ 外壁 材木 布基礎 笠木(2000*2)+(5500*5)+(5000)+10000+6000
A4: 屋根延長 | B4: =ROUNDUP(H4/0.7,-1) -> 25000 | C4: ㎡ | D4: 0 | E4: =B4*D4 -> 0 | F4: =IF(D4>0,ROW(),"") | H4: =9000+2000+3500+3000 -> 17500 | I4: =H4*D4 -> 0 | J4: =1-I4/E4 -> #DIV/0! | K4: (屋根、野地板、軒天 大工手間、材木 9000+2000+3500+3000
A5: FRP防水 | B5: =ROUNDUP(H5/0.7,-1) -> 20000 | C5: ㎡ | E5: =B5*D5 -> 0 | F5: =IF(D5>0,ROW(),"") | H5: 14000 | I5: =H5*D5 -> 0 | J5: =1-I5/E5 -> #DIV/0!
A6: 外壁出隅（14カ所超） | B6: =ROUNDUP(H6/0.7,-1) -> 30000 | C6: ㎡ | E6: =B6*D6 -> 0 | F6: =IF(D6>0,ROW(),"") | H6: 21000 | I6: =H6*D6 -> 0 | J6: =1-I6/E6 -> #DIV/0!
A7: パラペット立上り | B7: =ROUNDUP(H7/0.7,-1) -> 15000 | C7: m | E7: =B7*D7 -> 0 | F7: =IF(D7>0,ROW(),"") | H7: 10500 | I7: =H7*D7 -> 0 | J7: =1-I7/E7 -> #DIV/0!
A8: 深基礎A（40cmまで） | B8: =ROUNDUP(H8/0.7,-1) -> 22000 | C8: m | E8: =B8*D8 -> 0 | F8: =IF(D8>0,ROW(),"") | H8: 15400 | I8: =H8*D8 -> 0 | J8: =1-I8/E8 -> #DIV/0!
A9: 深基礎B（90cmまで） | B9: =ROUNDUP(H9/0.7,-1) -> 56000 | C9: m | E9: =B9*D9 -> 0 | F9: =IF(D9>0,ROW(),"") | H9: 39200 | I9: =H9*D9 -> 0 | J9: =1-I9/E9 -> #DIV/0!
A10: 勝手口ｾｯﾄ | B10: =ROUNDUP(H10/0.7,-1) -> 144000 | C10: 式 | E10: =B10*D10 -> 0 | F10: =IF(D10>0,ROW(),"") | H10: 100800 | I10: =H10*D10 -> 0 | J10: =1-I10/E10 -> #DIV/0!
A11: サッシ追加（ポイント超過分） | B11: =ROUNDUP(H11/0.7,-1) -> 45000 | C11: P | E11: =B11*D11 -> 0 | F11: =IF(D11>0,ROW(),"") | H11: 31500 | I11: =H11*D11 -> 0 | J11: =1-I11/E11 -> #DIV/0! | K11: 標準18ポイント 0.825㎡以下1ﾎﾟｲﾝﾄ それを超えると２ﾎﾟｲﾝﾄ ９尺巾サッシは3ﾎﾟｲﾝﾄとする
A12: 建具追加（リビングドア） | B12: =ROUNDUP(H12/0.7,-1) -> 40000 | C12: 円 | E12: =B12*D12 -> 0 | F12: =IF(D12>0,ROW(),"") | H12: 28000 | I12: =H12*D12 -> 0 | J12: =1-I12/E12 -> #DIV/0! | K12: 標準１台
A13: 建具追加（3尺巾） | B13: =ROUNDUP(H13/0.7,-1) -> 30000 | C13: 円 | D13: 2 | E13: =B13*D13 -> 60000 | F13: =IF(D13>0,ROW(),"") -> 13 | H13: 21000 | I13: =H13*D13 -> 42000 | J13: =1-I13/E13 -> 0.3 | K13: 標準8台
A14: 建具追加（6尺巾） | B14: =ROUNDUP(H14/0.7,-1) -> 60000 | C14: 円 | E14: =B14*D14 -> 0 | F14: =IF(D14>0,ROW(),"") | H14: 42000 | I14: =H14*D14 -> 0 | J14: =1-I14/E14 -> #DIV/0! | K14: 標準１台
A15: オプション工事 | B15: =ROUNDUP(H15/0.7,-1) -> 2000000 | C15: ㎡ | E15: =B15*D15 -> 0 | F15: =IF(D15>0,ROW(),"") | H15: 1400000 | I15: =H15*D15 -> 0 | J15: =1-I15/E15 -> #DIV/0!
B16: =ROUNDUP(H16/0.7,-1) -> 0 | C16: ㎡ | E16: =B16*D16 -> 0 | F16: =IF(D16>0,ROW(),"") | I16: =H16*D16 -> 0 | J16: =1-I16/E16 -> #DIV/0!
B17: =ROUNDUP(H17/0.7,-1) -> 0 | C17: ㎡ | E17: =B17*D17 -> 0 | F17: =IF(D17>0,ROW(),"") | I17: =H17*D17 -> 0 | J17: =1-I17/E17 -> #DIV/0!
A18: ＊＊＊ | B18: =ROUNDUP(H18/0.7,-1) -> 0 | E18: =B18*D18 -> 0 | F18: =IF(D18>0,ROW(),"") | I18: =H18*D18 -> 0 | J18: =1-I18/E18 -> #DIV/0!
A19: ＊＊＊ | B19: =ROUNDUP(H19/0.7,-1) -> 0 | E19: =B19*D19 -> 0 | F19: =IF(D19>0,ROW(),"") | I19: =H19*D19 -> 0 | J19: =1-I19/E19 -> #DIV/0!
A20: 外壁 破風鼻隠板 | B20: =ROUNDUP(H20/0.7,-1) -> 3000 | C20: ｍ | E20: =B20*D20 -> 0 | F20: =IF(D20>0,ROW(),"") | H20: 2100 | I20: =H20*D20 -> 0 | J20: =1-I20/E20 -> #DIV/0!
A21: 軒天 t5ｍｍ木目調板 | B21: =ROUNDUP(H21/0.7,-1) -> 4000 | C21: ㎡ | E21: =B21*D21 -> 0 | F21: =IF(D21>0,ROW(),"") | H21: 2800 | I21: =H21*D21 -> 0 | J21: =1-I21/E21 -> #DIV/0!
A22: 軒天 外壁材使用 | B22: =ROUNDUP(H22/0.7,-1) -> 9000 | C22: ㎡ | E22: =B22*D22 -> 0 | F22: =IF(D22>0,ROW(),"") | H22: 6300 | I22: =H22*D22 -> 0 | J22: =1-I22/E22 -> #DIV/0!
A23: フロアタイル追加（9㎡超え） | B23: =ROUNDUP(H23/0.7,-1) -> 5000 | C23: 式 | E23: =B23*D23 -> 0 | F23: =IF(D23>0,ROW(),"") | H23: 3500 | I23: =H23*D23 -> 0 | J23: =1-I23/E23 -> #DIV/0!
A24: 積層材カウンター | B24: =ROUNDUP(H24/0.7,-1) -> 30000 | C24: 円/㎡ | E24: =B24*D24 -> 0 | F24: =IF(D24>0,ROW(),"") | H24: 21000 | I24: =H24*D24 -> 0 | J24: =1-I24/E24 -> #DIV/0!
A25: 積層材カウンター、棚類（１ヵ所1.0㎡以下の棚） | B25: =ROUNDUP(H25/0.7,-1) -> 40000 | C25: 円/㎡ | E25: =B25*D25 -> 0 | F25: =IF(D25>0,ROW(),"") | H25: 28000 | I25: =H25*D25 -> 0 | J25: =1-I25/E25 -> #DIV/0!
A26: 3尺可動棚追加 | B26: =ROUNDUP(H26/0.7,-1) -> 26000 | C26: ヵ所 | D26: 1 | E26: =B26*D26 -> 26000 | F26: =IF(D26>0,ROW(),"") -> 26 | H26: 18200 | I26: =H26*D26 -> 18200 | J26: =1-I26/E26 -> 0.3
A27: 6尺可動棚追加 | B27: =ROUNDUP(H27/0.7,-1) -> 39000 | C27: ヵ所 | D27: 1 | E27: =B27*D27 -> 39000 | F27: =IF(D27>0,ROW(),"") -> 27 | H27: 27300 | I27: =H27*D27 -> 27300 | J27: =1-I27/E27 -> 0.3
A28: 6尺枕棚＋ハンガーパイプ | B28: =ROUNDUP(H28/0.7,-1) -> 14800 | C28: 式 | D28: 1 | E28: =B28*D28 -> 14800 | F28: =IF(D28>0,ROW(),"") -> 28 | H28: 10360 | I28: =H28*D28 -> 10360 | J28: =1-I28/E28 -> 0.3
A29: UB 折れ戸→ドア変更 | B29: =ROUNDUP(H29/0.7,-1) -> 0 | C29: 式 | E29: =B29*D29 -> 0 | F29: =IF(D29>0,ROW(),"") | I29: =H29*D29 -> 0 | J29: =1-I29/E29 -> #DIV/0!
A30: ＊＊＊ | B30: =ROUNDUP(H30/0.7,-1) -> 0 | C30: 式 | E30: =B30*D30 -> 0 | F30: =IF(D30>0,ROW(),"") | I30: =H30*D30 -> 0 | J30: =1-I30/E30 -> #DIV/0!
A31: ＊＊＊ | B31: =ROUNDUP(H31/0.7,-1) -> 0 | C31: 式 | E31: =B31*D31 -> 0 | F31: =IF(D31>0,ROW(),"") | I31: =H31*D31 -> 0 | J31: =1-I31/E31 -> #DIV/0!
A32: ＊＊＊ | B32: =ROUNDUP(H32/0.7,-1) -> 0 | C32: 式 | E32: =B32*D32 -> 0 | F32: =IF(D32>0,ROW(),"") | I32: =H32*D32 -> 0 | J32: =1-I32/E32 -> #DIV/0!
A33: 洗面化粧台EV W1200に変更 | B33: =ROUNDUP(H33/0.7,-1) -> 0 | C33: 式 | E33: =B33*D33 -> 0 | F33: =IF(D33>0,ROW(),"") | I33: =H33*D33 -> 0 | J33: =1-I33/E33 -> #DIV/0!
A34: 洗面化粧台EV W750・W900 | B34: =ROUNDUP(H34/0.7,-1) -> 96430 | C34: 式 | E34: =B34*D34 -> 0 | F34: =IF(D34>0,ROW(),"") | H34: 67500 | I34: =H34*D34 -> 0 | J34: =1-I34/E34 -> #DIV/0!
A35: ＊＊＊ | B35: =ROUNDUP(H35/0.7,-1) -> 0 | C35: 式 | E35: =B35*D35 -> 0 | F35: =IF(D35>0,ROW(),"") | I35: =H35*D35 -> 0 | J35: =1-I35/E35 -> #DIV/0!
A36: ＊＊＊ | B36: =ROUNDUP(H36/0.7,-1) -> 0 | C36: 式 | E36: =B36*D36 -> 0 | F36: =IF(D36>0,ROW(),"") | I36: =H36*D36 -> 0 | J36: =1-I36/E36 -> #DIV/0!
A37: ＊＊＊ | B37: =ROUNDUP(H37/0.7,-1) -> 0 | C37: 式 | E37: =B37*D37 -> 0 | F37: =IF(D37>0,ROW(),"") | I37: =H37*D37 -> 0 | J37: =1-I37/E37 -> #DIV/0!
A38: キッチン サイドフード | B38: =ROUNDUP(H38/0.7,-1) -> 60000 | C38: 式 | E38: =B38*D38 -> 0 | F38: =IF(D38>0,ROW(),"") | H38: 42000 | I38: =H38*D38 -> 0 | J38: =1-I38/E38 -> #DIV/0!
A39: LIXIL背面カウンター収納L1800 引出+オープン | B39: =ROUNDUP(H39/0.7,-1) -> 95000 | C39: 式 | E39: =B39*D39 -> 0 | F39: =IF(D39>0,ROW(),"") | H39: 66500 | I39: =H39*D39 -> 0 | J39: =1-I39/E39 -> #DIV/0!
A40: ＊＊＊ | B40: =ROUNDUP(H40/0.7,-1) -> 0 | C40: コ | E40: =B40*D40 -> 0 | F40: =IF(D40>0,ROW(),"") | I40: =H40*D40 -> 0 | J40: =1-I40/E40 -> #DIV/0!
...

Sheet 棚拾い表
A1: 家具・棚工事 標準数量との差額
A2: 部 位 | B2: キッチン | C2: カウンタ- | D2: ｱｰﾄﾗﾝﾊﾞｰOﾀｲﾌﾟ奥行300以下 | G2: ｱｰﾄﾗﾝﾊﾞｰOﾀｲﾌﾟ奥行301以上 | J2: 棚金物 | L2: フリーメイド幅6尺以下 | O2: フリーメイド幅9尺 | R2: 方立板 | S2: 畳コーナー下 | T2: トイレ棚
A3: PGH全棟共通 標準数量 | B3: L型カウンター | C3: 積層材㎥ | D3: 幅450棚 | E3: 幅900棚 | F3: 幅1820棚 | G3: 幅450棚 | H3: 幅900棚 | I3: 幅1820棚 | J3: 棚柱ｾｯﾄ | K3: ｱｰﾑﾊﾝｸﾞ棚受 | L3: ノダ枕棚 | M3: ノダ中段棚 | N3: ノダパイプ | O3: ノダ枕棚 | P3: ノダ中段棚 | Q3: ノダパイプ | R3: ランバーｔ27 | S3: 引き出し | T3: 幅3尺 | U3: 合計金額 | AA3: アートランバー棚t=20
B4: -1 | F4: -3 | J4: -1 | L4: -6 | M4: -1 | N4: -4 | T4: -2 | V4: ノダ（白） | W4: 中段 | X4: 枕棚 | Y4: パイプ | AB4: 奥行300 | AC4: D450 | AD4: D600 | AE4: D910
V5: 0.5間 | W5: =13000*0.4 -> 5200 | X5: =9300*0.4 -> 3720 | AA5: 幅350 | AB5: =2300*0.4 -> 920 | AC5: =2900*0.4 -> 1160 | AG5: ｱｰﾑﾊﾝｸﾞｓｓ182 | AH5: 棚受け200 | AI5: 棚受け250 | AJ5: 棚受け300 | AK5: 棚受け450
B6: 1 | F6: 3 | J6: 1 | L6: 6 | M6: 1 | N6: 4 | T6: 2 | V6: 0.45間 | W6: =19000*0.4 -> 7600 | X6: =13000*0.4 -> 5200 | AA6: 幅450 | AB6: =2700*0.4 -> 1080 | AC6: =3500*0.4 -> 1400 | AG6: =7300*0.55 -> 4015 | AH6: =2200*0.55 -> 1210 | AI6: =2300*0.55 -> 1265 | AJ6: =2700*0.55 -> 1485 | AK6: =3700*0.55 -> 2035
V7: 1.0間 | W7: =20000*0.4 -> 8000 | X7: =14000*0.4 -> 5600 | Y7: =6000*0.5 -> 3000 | AA7: 幅600 | AB7: =3400*0.4 -> 1360 | AC7: =4400*0.4 -> 1760
V8: 1.5間 | W8: =37000*0.4 -> 14800 | X8: =26000*0.4 -> 10400 | Y8: 5050 | AA8: 幅900 | AB8: =4900*0.4 -> 1960 | AC8: =6200*0.4 -> 2480 | AG8: 棚柱ｾｯﾄ（白） | AI8: 棚受１ｾｯﾄ
W9: =6000*0.5 -> 3000 | AA9: 幅1450 | AB9: =6500*0.4 -> 2600 | AC9: =8800*0.4 -> 3520 | AG9: 12×1820 | AH9: =13900*0.5 -> 6950 | AI9: =600*0.5 -> 300
V10: 積層材原価 | W10: ゴム（ノダ） | X10: アカシア | Y10: ホワイトアッシュ | AA10: 幅1810 | AB10: =7200*0.4 -> 2880 | AC10: =10000*0.4 -> 4000 | AD10: =13100*0.4 -> 5240 | AE10: =18200*0.4 -> 7280
L11: 1 | N11: 1 | V11: １㎥当り | W11: 610000 | X11: 650000 | Y11: 800000 | AG11: ノダ×0.285 カウンタ×0.34- 枕棚×0.4
Y12: 巾ハギ↑ | AA12: アートランバー棚t=27（収納仕切壁用） | AG12: 南海は×0.4（金物0.5）
AA13: 1か所 | AB13: D300 | AC13: D450 | AD13: D600 | AE13: D910 | AG13: 2階洗面配管 | AH13: 22000 | AI13: 原価
AA14: 高さ2410 | AB14: =12400*0.4 -> 4960 | AC14: =17000*0.4 -> 6800 | AD14: =21100*0.4 -> 8440 | AE14: =30100*0.4 -> 12040
AA15: 高さ2700 | AB15: =13100*0.4 -> 5240 | AC15: =18000*0.4 -> 7200 | AD15: =22800*0.4 -> 9120 | AE15: =32700*0.4 -> 13080 | AG15: 畳下引出し
A17: 合計数量 | B17: =SUM(B4:B16) -> 0 | C17: =SUM(C4:C16) -> 0 | D17: =SUM(D4:D16) -> 0 | E17: =SUM(E4:E16) -> 0 | F17: =SUM(F4:F16) -> 0 | G17: =SUM(G4:G16) -> 0 | H17: =SUM(H4:H16) -> 0 | I17: =SUM(I4:I16) -> 0 | ... T17: =SUM(T4:T16) -> 0
A18: 材工価格 | B18: =ROUNDUP(B21/0.7,-1) -> 0 | C18: =ROUNDUP(C21/0.7,-1) -> 0 | D18: =ROUNDUP(D21/0.7,-1) -> 0 | E18: =ROUNDUP(E21/0.7,-1) -> 0 | F18: =ROUNDUP(F21/0.7,-1) -> 0 | G18: =ROUNDUP(G21/0.7,-1) -> 0 | H18: =ROUNDUP(H21/0.7,-1) -> 0 | I18: =ROUNDUP(I21/0.7,-1) -> 0 | ... T18: =ROUNDUP(T21/0.7,-1) -> 0 | U18: =ROUNDUP(SUM(B18:T18),-2) -> 14800 | V18: ←売価（利益率30％）
A19: 原価材料 | B19: =B17*25500 -> 0 | C19: =C17*800000 -> 0 | D19: =D17*(1080+300) -> 0 | E19: =E17*(1960+300) -> 0 | F19: =F17*(2880+300) -> 0 | G19: =G17*(1400+300) -> 0 | H19: =H17*(2480+300) -> 0 | I19: =I17*(4000+300) -> 0 | J19: =J17*6950 -> 0 | K19: =K17*2000 -> 0 | L19: =L17*5600 -> 5600 | M19: =M17*8000 -> 0 | N19: =N17*3000 -> 3000 | O19: =O17*10400 -> 0 | P19: =P17*14800 -> 0 | Q19: =Q17*5050 -> 0 | R19: =R17*(7200+500) -> 0 | S19: =S17*35000 -> 0 | T19: =T17*(2880+850) -> 0 | U19: =SUM(B19:T19) -> 8600
A20: 原価施工費 | B20: =B19*0.2 -> 0 | C20: =C19*0.2 -> 0 | D20: =D19*0.2 -> 0 | E20: =E19*0.2 -> 0 | F20: =F19*0.2 -> 0 | G20: =G19*0.2 -> 0 | H20: =H19*0.2 -> 0 | I20: =I19*0.2 -> 0 | ... T20: =T19*0.2 -> 0 | U20: =SUM(B20:T20) -> 1720
A21: 合計金額 | B21: =SUM(B19:B20) -> 0 | C21: =SUM(C19:C20) -> 0 | D21: =SUM(D19:D20) -> 0 | E21: =SUM(E19:E20) -> 0 | F21: =SUM(F19:F20) -> 0 | G21: =SUM(G19:G20) -> 0 | H21: =SUM(H19:H20) -> 0 | I21: =SUM(I19:I20) -> 0 | ... T21: =SUM(T19:T20) -> 0 | U21: =(U18*0.7) -> 10360 | V21: ←追加原価
C22: 650000→800000変更 | V22: マイナスは減額おこさない。

Sheet 抽出オプション
A1: ■オプション工事 | B1: =#REF! -> #REF! | C1: =#REF! -> #REF! | D1: =#REF! -> #REF! | E1: =SUM(E3:E234) -> 1779800
A2: 項 目 | B2: 単価 | C2: 単位 | D2: 数量 | E2: 税抜金額 | H2: 原価単価 | I2: 原価合計 | J2: 利益率
A3: =IFERROR(INDEX(全オプション!A:A,SMALL(全オプション!$F:$F,ROW(A1))),"") -> 建具追加（3尺巾） | B3: =IFERROR(INDEX(全オプション!B:B,SMALL(全オプション!$F:$F,ROW(B1))),"") -> 30000 | C3: =IFERROR(INDEX(全オプション!C:C,SMALL(全オプション!$F:$F,ROW(C1))),"") -> 円 | D3: =IFERROR(INDEX(全オプション!D:D,SMALL(全オプション!$F:$F,ROW(D1))),"") -> 2 | E3: =IFERROR(INDEX(全オプション!E:E,SMALL(全オプション!$F:$F,ROW(E1))),"") -> 60000 | F3: =IFERROR(INDEX(全オプション!F:F,SMALL(全オプション!$F:$F,ROW(F1))),"") -> 13 | H3: =IFERROR(INDEX(全オプション!H:H,SMALL(全オプション!$F:$F,ROW(H1))),"") -> 21000 | I3: =IFERROR(INDEX(全オプション!I:I,SMALL(全オプション!$F:$F,ROW(I1))),"") -> 42000 | J3: =IFERROR(INDEX(全オプション!J:J,SMALL(全オプション!$F:$F,ROW(J1))),"") -> 0.3
A4: =IFERROR(INDEX(全オプション!A:A,SMALL(全オプション!$F:$F,ROW(A2))),"") -> 3尺可動棚追加 | B4: =IFERROR(INDEX(全オプション!B:B,SMALL(全オプション!$F:$F,ROW(B2))),"") -> 26000 | C4: =IFERROR(INDEX(全オプション!C:C,SMALL(全オプション!$F:$F,ROW(C2))),"") -> ヵ所 | D4: =IFERROR(INDEX(全オプション!D:D,SMALL(全オプション!$F:$F,ROW(D2))),"") -> 1 | E4: =IFERROR(INDEX(全オプション!E:E,SMALL(全オプション!$F:$F,ROW(E2))),"") -> 26000 | F4: =IFERROR(INDEX(全オプション!F:F,SMALL(全オプション!$F:$F,ROW(F2))),"") -> 26 | H4: =IFERROR(INDEX(全オプション!H:H,SMALL(全オプション!$F:$F,ROW(H2))),"") -> 18200 | I4: =IFERROR(INDEX(全オプション!I:I,SMALL(全オプション!$F:$F,ROW(I2))),"") -> 18200 | J4: =IFERROR(INDEX(全オプション!J:J,SMALL(全オプション!$F:$F,ROW(J2))),"") -> 0.3
A5: =IFERROR(INDEX(全オプション!A:A,SMALL(全オプション!$F:$F,ROW(A3))),"") -> 6尺可動棚追加 | B5: =IFERROR(INDEX(全オプション!B:B,SMALL(全オプション!$F:$F,ROW(B3))),"") -> 39000 | C5: =IFERROR(INDEX(全オプション!C:C,SMALL(全オプション!$F:$F,ROW(C3))),"") -> ヵ所 | D5: =IFERROR(INDEX(全オプション!D:D,SMALL(全オプション!$F:$F,ROW(D3))),"") -> 1 | E5: =IFERROR(INDEX(全オプション!E:E,SMALL(全オプション!$F:$F,ROW(E3))),"") -> 39000 | F5: =IFERROR(INDEX(全オプション!F:F,SMALL(全オプション!$F:$F,ROW(F3))),"") -> 27 | H5: =IFERROR(INDEX(全オプション!H:H,SMALL(全オプション!$F:$F,ROW(H3))),"") -> 27300 | I5: =IFERROR(INDEX(全オプション!I:I,SMALL(全オプション!$F:$F,ROW(I3))),"") -> 27300 | J5: =IFERROR(INDEX(全オプション!J:J,SMALL(全オプション!$F:$F,ROW(J3))),"") -> 0.3
A6: =IFERROR(INDEX(全オプション!A:A,SMALL(全オプション!$F:$F,ROW(A4))),"") -> 6尺枕棚＋ハンガーパイプ | B6: =IFERROR(INDEX(全オプション!B:B,SMALL(全オプション!$F:$F,ROW(B4))),"") -> 14800 | C6: =IFERROR(INDEX(全オプション!C:C,SMALL(全オプション!$F:$F,ROW(C4))),"") -> 式 | D6: =IFERROR(INDEX(全オプション!D:D,SMALL(全オプション!$F:$F,ROW(D4))),"") -> 1 | E6: =IFERROR(INDEX(全オプション!E:E,SMALL(全オプション!$F:$F,ROW(E4))),"") -> 14800 | F6: =IFERROR(INDEX(全オプション!F:F,SMALL(全オプション!$F:$F,ROW(F4))),"") -> 28 | H6: =IFERROR(INDEX(全オプション!H:H,SMALL(全オプション!$F:$F,ROW(H4))),"") -> 10360 | I6: =IFERROR(INDEX(全オプション!I:I,SMALL(全オプション!$F:$F,ROW(I4))),"") -> 10360 | J6: =IFERROR(INDEX(全オプション!J:J,SMALL(全オプション!$F:$F,ROW(J4))),"") -> 0.3
A7: =IFERROR(INDEX(全オプション!A:A,SMALL(全オプション!$F:$F,ROW(A5))),"") -> オプション工事予算 | B7: =IFERROR(INDEX(全オプション!B:B,SMALL(全オプション!$F:$F,ROW(B5))),"") -> 1640000 | C7: =IFERROR(INDEX(全オプション!C:C,SMALL(全オプション!$F:$F,ROW(C5))),"") -> 式 | D7: =IFERROR(INDEX(全オプション!D:D,SMALL(全オプション!$F:$F,ROW(D5))),"") -> 1 | E7: =IFERROR(INDEX(全オプション!E:E,SMALL(全オプション!$F:$F,ROW(E5))),"") -> 1640000 | F7: =IFERROR(INDEX(全オプション!F:F,SMALL(全オプション!$F:$F,ROW(F5))),"") -> 66 | H7: =IFERROR(INDEX(全オプション!H:H,SMALL(全オプション!$F:$F,ROW(H5))),"") -> 1148000 | I7: =IFERROR(INDEX(全オプション!I:I,SMALL(全オプション!$F:$F,ROW(I5))),"") -> 1148000 | J7: =IFERROR(INDEX(全オプション!J:J,SMALL(全オプション!$F:$F,ROW(J5))),"") -> 0.3
A8: =IFERROR(INDEX(全オプション!A:A,SMALL(全オプション!$F:$F,ROW(A6))),"") | B8: =IFERROR(INDEX(全オプション!B:B,SMALL(全オプション!$F:$F,ROW(B6))),"") | C8: =IFERROR(INDEX(全オプション!C:C,SMALL(全オプション!$F:$F,ROW(C6))),"") | D8: =IFERROR(INDEX(全オプション!D:D,SMALL(全オプション!$F:$F,ROW(D6))),"") | E8: =IFERROR(INDEX(全オプション!E:E,SMALL(全オプション!$F:$F,ROW(E6))),"") | F8: =IFERROR(INDEX(全オプション!F:F,SMALL(全オプション!$F:$F,ROW(F6))),"") | H8: =IFERROR(INDEX(全オプション!H:H,SMALL(全オプション!$F:$F,ROW(H6))),"") | I8: =IFERROR(INDEX(全オプション!I:I,SMALL(全オプション!$F:$F,ROW(I6))),"") | J8: =IFERROR(INDEX(全オプション!J:J,SMALL(全オプション!$F:$F,ROW(J6))),"")
A9: =IFERROR(INDEX(全オプション!A:A,SMALL(全オプション!$F:$F,ROW(A7))),"") | B9: =IFERROR(INDEX(全オプション!B:B,SMALL(全オプション!$F:$F,ROW(B7))),"") | C9: =IFERROR(INDEX(全オプション!C:C,SMALL(全オプション!$F:$F,ROW(C7))),"") | D9: =IFERROR(INDEX(全オプション!D:D,SMALL(全オプション!$F:$F,ROW(D7))),"") | E9: =IFERROR(INDEX(全オプション!E:E,SMALL(全オプション!$F:$F,ROW(E7))),"") | F9: =IFERROR(INDEX(全オプション!F:F,SMALL(全オプション!$F:$F,ROW(F7))),"") | H9: =IFERROR(INDEX(全オプション!H:H,SMALL(全オプション!$F:$F,ROW(H7))),"") | I9: =IFERROR(INDEX(全オプション!I:I,SMALL(全オプション!$F:$F,ROW(I7))),"") | J9: =IFERROR(INDEX(全オプション!J:J,SMALL(全オプション!$F:$F,ROW(J7))),"")
A10: =IFERROR(INDEX(全オプション!A:A,SMALL(全オプション!$F:$F,ROW(A8))),"") | B10: =IFERROR(INDEX(全オプション!B:B,SMALL(全オプション!$F:$F,ROW(B8))),"") | C10: =IFERROR(INDEX(全オプション!C:C,SMALL(全オプション!$F:$F,ROW(C8))),"") | D10: =IFERROR(INDEX(全オプション!D:D,SMALL(全オプション!$F:$F,ROW(D8))),"") | E10: =IFERROR(INDEX(全オプション!E:E,SMALL(全オプション!$F:$F,ROW(E8))),"") | F10: =IFERROR(INDEX(全オプション!F:F,SMALL(全オプション!$F:$F,ROW(F8))),"") | H10: =IFERROR(INDEX(全オプション!H:H,SMALL(全オプション!$F:$F,ROW(H8))),"") | I10: =IFERROR(INDEX(全オプション!I:I,SMALL(全オプション!$F:$F,ROW(I8))),"") | J10: =IFERROR(INDEX(全オプション!J:J,SMALL(全オプション!$F:$F,ROW(J8))),"")
A11: =IFERROR(INDEX(全オプション!A:A,SMALL(全オプション!$F:$F,ROW(A9))),"") | B11: =IFERROR(INDEX(全オプション!B:B,SMALL(全オプション!$F:$F,ROW(B9))),"") | C11: =IFERROR(INDEX(全オプション!C:C,SMALL(全オプション!$F:$F,ROW(C9))),"") | D11: =IFERROR(INDEX(全オプション!D:D,SMALL(全オプション!$F:$F,ROW(D9))),"") | E11: =IFERROR(INDEX(全オプション!E:E,SMALL(全オプション!$F:$F,ROW(E9))),"") | F11: =IFERROR(INDEX(全オプション!F:F,SMALL(全オプション!$F:$F,ROW(F9))),"") | H11: =IFERROR(INDEX(全オプション!H:H,SMALL(全オプション!$F:$F,ROW(H9))),"") | I11: =IFERROR(INDEX(全オプション!I:I,SMALL(全オプション!$F:$F,ROW(I9))),"") | J11: =IFERROR(INDEX(全オプション!J:J,SMALL(全オプション!$F:$F,ROW(J9))),"")
A12: =IFERROR(INDEX(全オプション!A:A,SMALL(全オプション!$F:$F,ROW(A10))),"") | B12: =IFERROR(INDEX(全オプション!B:B,SMALL(全オプション!$F:$F,ROW(B10))),"") | C12: =IFERROR(INDEX(全オプション!C:C,SMALL(全オプション!$F:$F,ROW(C10))),"") | D12: =IFERROR(INDEX(全オプション!D:D,SMALL(全オプション!$F:$F,ROW(D10))),"") | E12: =IFERROR(INDEX(全オプション!E:E,SMALL(全オプション!$F:$F,ROW(E10))),"") | F12: =IFERROR(INDEX(全オプション!F:F,SMALL(全オプション!$F:$F,ROW(F10))),"") | H12: =IFERROR(INDEX(全オプション!H:H,SMALL(全オプション!$F:$F,ROW(H10))),"") | I12: =IFERROR(INDEX(全オプション!I:I,SMALL(全オプション!$F:$F,ROW(I10))),"") | J12: =IFERROR(INDEX(全オプション!J:J,SMALL(全オプション!$F:$F,ROW(J10))),"")
A13: =IFERROR(INDEX(全オプション!A:A,SMALL(全オプション!$F:$F,ROW(A11))),"") | B13: =IFERROR(INDEX(全オプション!B:B,SMALL(全オプション!$F:$F,ROW(B11))),"") | C13: =IFERROR(INDEX(全オプション!C:C,SMALL(全オプション!$F:$F,ROW(C11))),"") | D13: =IFERROR(INDEX(全オプション!D:D,SMALL(全オプション!$F:$F,ROW(D11))),"") | E13: =IFERROR(INDEX(全オプション!E:E,SMALL(全オプション!$F:$F,ROW(E11))),"") | F13: =IFERROR(INDEX(全オプション!F:F,SMALL(全オプション!$F:$F,ROW(F11))),"") | H13: =IFERROR(INDEX(全オプション!H:H,SMALL(全オプション!$F:$F,ROW(H11))),"") | I13: =IFERROR(INDEX(全オプション!I:I,SMALL(全オプション!$F:$F,ROW(I11))),"") | J13: =IFERROR(INDEX(全オプション!J:J,SMALL(全オプション!$F:$F,ROW(J11))),"")
A14: =IFERROR(INDEX(全オプション!A:A,SMALL(全オプション!$F:$F,ROW(A12))),"") | B14: =IFERROR(INDEX(全オプション!B:B,SMALL(全オプション!$F:$F,ROW(B12))),"") | C14: =IFERROR(INDEX(全オプション!C:C,SMALL(全オプション!$F:$F,ROW(C12))),"") | D14: =IFERROR(INDEX(全オプション!D:D,SMALL(全オプション!$F:$F,ROW(D12))),"") | E14: =IFERROR(INDEX(全オプション!E:E,SMALL(全オプション!$F:$F,ROW(E12))),"") | F14: =IFERROR(INDEX(全オプション!F:F,SMALL(全オプション!$F:$F,ROW(F12))),"") | H14: =IFERROR(INDEX(全オプション!H:H,SMALL(全オプション!$F:$F,ROW(H12))),"") | I14: =IFERROR(INDEX(全オプション!I:I,SMALL(全オプション!$F:$F,ROW(I12))),"") | J14: =IFERROR(INDEX(全オプション!J:J,SMALL(全オプション!$F:$F,ROW(J12))),"")
... A19: =IFERROR(INDEX(全オプション!A:A,SMALL(全オプション!$F:$F,ROW(A17))),"") | B19: =IFERROR(INDEX(全オプション!B:B,SMALL(全オプション!$F:$F,ROW(B17))),"") | C19: =IFERROR(INDEX(全オプション!C:C,SMALL(全オプション!$F:$F,ROW(C17))),"") | D19: =IFERROR(INDEX(全オプション!D:D,SMALL(全オプション!$F:$F,ROW(D17))),"") | E19: =IFERROR(INDEX(全オプション!E:E,SMALL(全オプション!$F:$F,ROW(E17))),"") | F19: =IFERROR(INDEX(全オプション!F:F,SMALL(全オプション!$F:$F,ROW(F17))),"") | H19: =IFERROR(INDEX(全オプション!H:H,SMALL(全オプション!$F:$F,ROW(H17))),"") | I19: =IFERROR(INDEX(全オプション!I:I,SMALL(全オプション!$F:$F,ROW(I17))),"") | J19: =IFERROR(INDEX(全オプション!J:J,SMALL(全オプション!$F:$F,ROW(J17))),"")
A20: =IFERROR(INDEX(全オプション!A:A,SMALL(全オプション!$F:$F,ROW(A18))),"") | B20: =IFERROR(INDEX(全オプション!B:B,SMALL(全オプション!$F:$F,ROW(B18))),"") | C20: =IFERROR(INDEX(全オプション!C:C,SMALL(全オプション!$F:$F,ROW(C18))),"") | D20: =IFERROR(INDEX(全オプション!D:D,SMALL(全オプション!$F:$F,ROW(D18))),"") | E20: =IFERROR(INDEX(全オプション!E:E,SMALL(全オプション!$F:$F,ROW(E18))),"") | F20: =IFERROR(INDEX(全オプション!F:F,SMALL(全オプション!$F:$F,ROW(F18))),"") | H20: =IFERROR(INDEX(全オプション!H:H,SMALL(全オプション!$F:$F,ROW(H18))),"") | I20: =IFERROR(INDEX(全オプション!I:I,SMALL(全オプション!$F:$F,ROW(I18))),"") | J20: =IFERROR(INDEX(全オプション!J:J,SMALL(全オプション!$F:$F,ROW(J18))),"") | K20: ここ以下は表示されない
A21: =IFERROR(INDEX(全オプション!A:A,SMALL(全オプション!$F:$F,ROW(A19))),"") | B21: =IFERROR(INDEX(全オプション!B:B,SMALL(全オプション!$F:$F,ROW(B19))),"") | C21: =IFERROR(INDEX(全オプション!C:C,SMALL(全オプション!$F:$F,ROW(C19))),"") | D21: =IFERROR(INDEX(全オプション!D:D,SMALL(全オプション!$F:$F,ROW(D19))),"") | E21: =IFERROR(INDEX(全オプション!E:E,SMALL(全オプション!$F:$F,ROW(E19))),"") | F21: =IFERROR(INDEX(全オプション!F:F,SMALL(全オプション!$F:$F,ROW(F19))),"") | H21: =IFERROR(INDEX(全オプション!H:H,SMALL(全オプション!$F:$F,ROW(H19))),"") | I21: =IFERROR(INDEX(全オプション!I:I,SMALL(全オプション!$F:$F,ROW(I19))),"") | J21: =IFERROR(INDEX(全オプション!J:J,SMALL(全オプション!$F:$F,ROW(J19))),"")
A22: =IFERROR(INDEX(全オプション!A:A,SMALL(全オプション!$F:$F,ROW(A20))),"") | B22: =IFERROR(INDEX(全オプション!B:B,SMALL(全オプション!$F:$F,ROW(B20))),"") | C22: =IFERROR(INDEX(全オプション!C:C,SMALL(全オプション!$F:$F,ROW(C20))),"") | D22: =IFERROR(INDEX(全オプション!D:D,SMALL(全オプション!$F:$F,ROW(D20))),"") | E22: =IFERROR(INDEX(全オプション!E:E,SMALL(全オプション!$F:$F,ROW(E20))),"") | F22: =IFERROR(INDEX(全オプション!F:F,SMALL(全オプション!$F:$F,ROW(F20))),"") | H22: =IFERROR(INDEX(全オプション!H:H,SMALL(全オプション!$F:$F,ROW(H20))),"") | I22: =IFERROR(INDEX(全オプション!I:I,SMALL(全オプション!$F:$F,ROW(I20))),"") | J22: =IFERROR(INDEX(全オプション!J:J,SMALL(全オプション!$F:$F,ROW(J20))),"")
A23: =IFERROR(INDEX(全オプション!A:A,SMALL(全オプション!$F:$F,ROW(A21))),"") | B23: =IFERROR(INDEX(全オプション!B:B,SMALL(全オプション!$F:$F,ROW(B21))),"") | C23: =IFERROR(INDEX(全オプション!C:C,SMALL(全オプション!$F:$F,ROW(C21))),"") | D23: =IFERROR(INDEX(全オプション!D:D,SMALL(全オプション!$F:$F,ROW(D21))),"") | E23: =IFERROR(INDEX(全オプション!E:E,SMALL(全オプション!$F:$F,ROW(E21))),"") | F23: =IFERROR(INDEX(全オプション!F:F,SMALL(全オプション!$F:$F,ROW(F21))),"") | H23: =IFERROR(INDEX(全オプション!H:H,SMALL(全オプション!$F:$F,ROW(H21))),"") | I23: =IFERROR(INDEX(全オプション!I:I,SMALL(全オプション!$F:$F,ROW(I21))),"") | J23: =IFERROR(INDEX(全オプション!J:J,SMALL(全オプション!$F:$F,ROW(J21))),"")
A24: =IFERROR(INDEX(全オプション!A:A,SMALL(全オプション!$F:$F,ROW(A22))),"") | B24: =IFERROR(INDEX(全オプション!B:B,SMALL(全オプション!$F:$F,ROW(B22))),"") | C24: =IFERROR(INDEX(全オプション!C:C,SMALL(全オプション!$F:$F,ROW(C22))),"") | D24: =IFERROR(INDEX(全オプション!D:D,SMALL(全オプション!$F:$F,ROW(D22))),"") | E24: =IFERROR(INDEX(全オプション!E:E,SMALL(全オプション!$F:$F,ROW(E22))),"") | F24: =IFERROR(INDEX(全オプション!F:F,SMALL(全オプション!$F:$F,ROW(F22))),"") | H24: =IFERROR(INDEX(全オプション!H:H,SMALL(全オプション!$F:$F,ROW(H22))),"") | I24: =IFERROR(INDEX(全オプション!I:I,SMALL(全オプション!$F:$F,ROW(I22))),"") | J24: =IFERROR(INDEX(全オプション!J:J,SMALL(全オプション!$F:$F,ROW(J22))),"")
A25: =IFERROR(INDEX(全オプション!A:A,SMALL(全オプション!$F:$F,ROW(A23))),"") | B25: =IFERROR(INDEX(全オプション!B:B,SMALL(全オプション!$F:$F,ROW(B23))),"") | C25: =IFERROR(INDEX(全オプション!C:C,SMALL(全オプション!$F:$F,ROW(C23))),"") | D25: =IFERROR(INDEX(全オプション!D:D,SMALL(全オプション!$F:$F,ROW(D23))),"") | E25: =IFERROR(INDEX(全オプション!E:E,SMALL(全オプション!$F:$F,ROW(E23))),"") | F25: =IFERROR(INDEX(全オプション!F:F,SMALL(全オプション!$F:$F,ROW(F23))),"") | H25: =IFERROR(INDEX(全オプション!H:H,SMALL(全オプション!$F:$F,ROW(H23))),"") | I25: =IFERROR(INDEX(全オプション!I:I,SMALL(全オプション!$F:$F,ROW(I23))),"") | J25: =IFERROR(INDEX(全オプション!J:J,SMALL(全オプション!$F:$F,ROW(J23))),"")
A26: =IFERROR(INDEX(全オプション!A:A,SMALL(全オプション!$F:$F,ROW(A24))),"") | B26: =IFERROR(INDEX(全オプション!B:B,SMALL(全オプション!$F:$F,ROW(B24))),"") | C26: =IFERROR(INDEX(全オプション!C:C,SMALL(全オプション!$F:$F,ROW(C24))),"") | D26: =IFERROR(INDEX(全オプション!D:D,SMALL(全オプション!$F:$F,ROW(D24))),"") | E26: =IFERROR(INDEX(全オプション!E:E,SMALL(全オプション!$F:$F,ROW(E24))),"") | F26: =IFERROR(INDEX(全オプション!F:F,SMALL(全オプション!$F:$F,ROW(F24))),"") | H26: =IFERROR(INDEX(全オプション!H:H,SMALL(全オプション!$F:$F,ROW(H24))),"") | I26: =IFERROR(INDEX(全オプション!I:I,SMALL(全オプション!$F:$F,ROW(I24))),"") | J26: =IFERROR(INDEX(全オプション!J:J,SMALL(全オプション!$F:$F,ROW(J24))),"")
A27: =IFERROR(INDEX(全オプション!A:A,SMALL(全オプション!$F:$F,ROW(A25))),"") | B27: =IFERROR(INDEX(全オプション!B:B,SMALL(全オプション!$F:$F,ROW(B25))),"") | C27: =IFERROR(INDEX(全オプション!C:C,SMALL(全オプション!$F:$F,ROW(C25))),"") | D27: =IFERROR(INDEX(全オプション!D:D,SMALL(全オプション!$F:$F,ROW(D25))),"") | E27: =IFERROR(INDEX(全オプション!E:E,SMALL(全オプション!$F:$F,ROW(E25))),"") | F27: =IFERROR(INDEX(全オプション!F:F,SMALL(全オプション!$F:$F,ROW(F25))),"") | H27: =IFERROR(INDEX(全オプション!H:H,SMALL(全オプション!$F:$F,ROW(H25))),"") | I27: =IFERROR(INDEX(全オプション!I:I,SMALL(全オプション!$F:$F,ROW(I25))),"") | J27: =IFERROR(INDEX(全オプション!J:J,SMALL(全オプション!$F:$F,ROW(J25))),"")
A28: =IFERROR(INDEX(全オプション!A:A,SMALL(全オプション!$F:$F,ROW(A26))),"") | B28: =IFERROR(INDEX(全オプション!B:B,SMALL(全オプション!$F:$F,ROW(B26))),"") | C28: =IFERROR(INDEX(全オプション!C:C,SMALL(全オプション!$F:$F,ROW(C26))),"") | D28: =IFERROR(INDEX(全オプション!D:D,SMALL(全オプション!$F:$F,ROW(D26))),"") | E28: =IFERROR(INDEX(全オプション!E:E,SMALL(全オプション!$F:$F,ROW(E26))),"") | F28: =IFERROR(INDEX(全オプション!F:F,SMALL(全オプション!$F:$F,ROW(F26))),"") | H28: =IFERROR(INDEX(全オプション!H:H,SMALL(全オプション!$F:$F,ROW(H26))),"") | I28: =IFERROR(INDEX(全オプション!I:I,SMALL(全オプション!$F:$F,ROW(I26))),"") | J28: =IFERROR(INDEX(全オプション!J:J,SMALL(全オプション!$F:$F,ROW(J26))),"")
A29: =IFERROR(INDEX(全オプション!A:A,SMALL(全オプション!$F:$F,ROW(A27))),"") | B29: =IFERROR(INDEX(全オプション!B:B,SMALL(全オプション!$F:$F,ROW(B27))),"") | C29: =IFERROR(INDEX(全オプション!C:C,SMALL(全オプション!$F:$F,ROW(C27))),"") | D29: =IFERROR(INDEX(全オプション!D:D,SMALL(全オプション!$F:$F,ROW(D27))),"") | E29: =IFERROR(INDEX(全オプション!E:E,SMALL(全オプション!$F:$F,ROW(E27))),"") | F29: =IFERROR(INDEX(全オプション!F:F,SMALL(全オプション!$F:$F,ROW(F27))),"") | H29: =IFERROR(INDEX(全オプション!H:H,SMALL(全オプション!$F:$F,ROW(H27))),"") | I29: =IFERROR(INDEX(全オプション!I:I,SMALL(全オプション!$F:$F,ROW(I27))),"") | J29: =IFERROR(INDEX(全オプション!J:J,SMALL(全オプション!$F:$F,ROW(J27))),"")
A30: =IFERROR(INDEX(全オプション!A:A,SMALL(全オプション!$F:$F,ROW(A28))),"") | B30: =IFERROR(INDEX(全オプション!B:B,SMALL(全オプション!$F:$F,ROW(B28))),"") | C30: =IFERROR(INDEX(全オプション!C:C,SMALL(全オプション!$F:$F,ROW(C28))),"") | D30: =IFERROR(INDEX(全オプション!D:D,SMALL(全オプション!$F:$F,ROW(D28))),"") | E30: =IFERROR(INDEX(全オプション!E:E,SMALL(全オプション!$F:$F,ROW(E28))),"") | F30: =IFERROR(INDEX(全オプション!F:F,SMALL(全オプション!$F:$F,ROW(F28))),"") | H30: =IFERROR(INDEX(全オプション!H:H,SMALL(全オプション!$F:$F,ROW(H28))),"") | I30: =IFERROR(INDEX(全オプション!I:I,SMALL(全オプション!$F:$F,ROW(I28))),"") | J30: =IFERROR(INDEX(全オプション!J:J,SMALL(全オプション!$F:$F,ROW(J28))),"")
A31: =IFERROR(INDEX(全オプション!A:A,SMALL(全オプション!$F:$F,ROW(A29))),"") | B31: =IFERROR(INDEX(全オプション!B:B,SMALL(全オプション!$F:$F,ROW(B29))),"") | C31: =IFERROR(INDEX(全オプション!C:C,SMALL(全オプション!$F:$F,ROW(C29))),"") | D31: =IFERROR(INDEX(全オプション!D:D,SMALL(全オプション!$F:$F,ROW(D29))),"") | E31: =IFERROR(INDEX(全オプション!E:E,SMALL(全オプション!$F:$F,ROW(E29))),"") | F31: =IFERROR(INDEX(全オプション!F:F,SMALL(全オプション!$F:$F,ROW(F29))),"") | H31: =IFERROR(INDEX(全オプション!H:H,SMALL(全オプション!$F:$F,ROW(H29))),"") | I31: =IFERROR(INDEX(全オプション!I:I,SMALL(全オプション!$F:$F,ROW(I29))),"") | J31: =IFERROR(INDEX(全オプション!J:J,SMALL(全オプション!$F:$F,ROW(J29))),"")
A32: =IFERROR(INDEX(全オプション!A:A,SMALL(全オプション!$F:$F,ROW(A30))),"") | B32: =IFERROR(INDEX(全オプション!B:B,SMALL(全オプション!$F:$F,ROW(B30))),"") | C32: =IFERROR(INDEX(全オプション!C:C,SMALL(全オプション!$F:$F,ROW(C30))),"") | D32: =IFERROR(INDEX(全オプション!D:D,SMALL(全オプション!$F:$F,ROW(D30))),"") | E32: =IFERROR(INDEX(全オプション!E:E,SMALL(全オプション!$F:$F,ROW(E30))),"") | F32: =IFERROR(INDEX(全オプション!F:F,SMALL(全オプション!$F:$F,ROW(F30))),"") | H32: =IFERROR(INDEX(全オプション!H:H,SMALL(全オプション!$F:$F,ROW(H30))),"") | I32: =IFERROR(INDEX(全オプション!I:I,SMALL(全オプション!$F:$F,ROW(I30))),"") | J32: =IFERROR(INDEX(全オプション!J:J,SMALL(全オプション!$F:$F,ROW(J30))),"")
... A234: =IFERROR(INDEX(全オプション!A:A,SMALL(全オプション!$F:$F,ROW(A232))),"") | B234: =IFERROR(INDEX(全オプション!B:B,SMALL(全オプション!$F:$F,ROW(B232))),"") | C234: =IFERROR(INDEX(全オプション!C:C,SMALL(全オプション!$F:$F,ROW(C232))),"") | D234: =IFERROR(INDEX(全オプション!D:D,SMALL(全オプション!$F:$F,ROW(D232))),"") | E234: =IFERROR(INDEX(全オプション!E:E,SMALL(全オプション!$F:$F,ROW(E232))),"") | F234: =IFERROR(INDEX(全オプション!F:F,SMALL(全オプション!$F:$F,ROW(F232))),"") | H234: =IFERROR(INDEX(全オプション!H:H,SMALL(全オプション!$F:$F,ROW(H232))),"") | I234: =IFERROR(INDEX(全オプション!I:I,SMALL(全オプション!$F:$F,ROW(I232))),"") | J234: =IFERROR(INDEX(全オプション!J:J,SMALL(全オプション!$F:$F,ROW(J232))),"")
